Workbook

Sheet ALL Unions
A1: Union | B1: Contract Name | C1: NECA Chapter | D1: NECA Division | E1: NECA State | F1: Rosendin Member | G1: Committee | H1: # of instructors
A2: 3 | B2: Northern CA - Operating Engineers | C2: =VLOOKUP(A2,'NECA Chapters(Debra)'!A:D,3,FALSE) -> New York City Chapter NECA | D2: =VLOOKUP(A2,'NECA Chapters(Debra)'!A:D,4,FALSE) -> New York City Division - 3 | E2: =VLOOKUP(A2,'NECA Chapters(Debra)'!A:D,2,FALSE) -> NY
A3: 6 | B3: 6 SF, CA - Inside Wireman | C3: =VLOOKUP(A3,'NECA Chapters(Debra)'!A:D,3,FALSE) -> San Francisco Chapter NECA | D3: =VLOOKUP(A3,'NECA Chapters(Debra)'!A:D,4,FALSE) -> San Francisco Division - 6 | E3: =VLOOKUP(A3,'NECA Chapters(Debra)'!A:D,2,FALSE) -> CA
A4: 11 | B4: 11 LA, CA - Inside Wireman | C4: =VLOOKUP(A4,'NECA Chapters(Debra)'!A:D,3,FALSE) -> Los Angeles County Chapter NECA | D4: =VLOOKUP(A4,'NECA Chapters(Debra)'!A:D,4,FALSE) -> Los Angeles Division - 11 | E4: =VLOOKUP(A4,'NECA Chapters(Debra)'!A:D,2,FALSE) -> CA
A5: 11 LB | B5: 11 Virginia - Laborers | C5: =VLOOKUP(A5,'NECA Chapters(Debra)'!A:D,3,FALSE) -> #N/A | D5: =VLOOKUP(A5,'NECA Chapters(Debra)'!A:D,4,FALSE) -> #N/A | E5: =VLOOKUP(A5,'NECA Chapters(Debra)'!A:D,2,FALSE) -> #N/A
A6: 12 OP | B6: Southern CA - Operating Engineers | C6: =VLOOKUP(A6,'NECA Chapters(Debra)'!A:D,3,FALSE) -> #N/A | D6: =VLOOKUP(A6,'NECA Chapters(Debra)'!A:D,4,FALSE) -> #N/A | E6: =VLOOKUP(A6,'NECA Chapters(Debra)'!A:D,2,FALSE) -> #N/A
A7: 20 | B7: 20 Arlington, TX - Inside Wireman | C7: =VLOOKUP(A7,'NECA Chapters(Debra)'!A:D,3,FALSE) -> North Texas Chapter NECA | D7: =VLOOKUP(A7,'NECA Chapters(Debra)'!A:D,4,FALSE) -> Dallas/Ft Worth Division - 20 | E7: =VLOOKUP(A7,'NECA Chapters(Debra)'!A:D,2,FALSE) -> TX
A8: 24 | B8: 24 Baltimore, MD - Inside Wireman | C8: =VLOOKUP(A8,'NECA Chapters(Debra)'!A:D,3,FALSE) -> Maryland Chapter NECA | D8: =VLOOKUP(A8,'NECA Chapters(Debra)'!A:D,4,FALSE) -> Baltimore Division - 24 | E8: =VLOOKUP(A8,'NECA Chapters(Debra)'!A:D,2,FALSE) -> MD
A9: 26 | B9: 26 DC Chapter - Inside Wireman | C9: =VLOOKUP(A9,'NECA Chapters(Debra)'!A:D,3,FALSE) -> Washington DC Chapter NECA | D9: =VLOOKUP(A9,'NECA Chapters(Debra)'!A:D,4,FALSE) -> Washington DC Division - 26 | E9: =VLOOKUP(A9,'NECA Chapters(Debra)'!A:D,2,FALSE) -> VA
A10: 47 L | B10: 47 L Southern CA - Line Construction | C10: =VLOOKUP(A10,'NECA Chapters(Debra)'!A:D,3,FALSE) -> #N/A | D10: =VLOOKUP(A10,'NECA Chapters(Debra)'!A:D,4,FALSE) -> #N/A | E10: =VLOOKUP(A10,'NECA Chapters(Debra)'!A:D,2,FALSE) -> #N/A
A11: 48 | B11: 48 Portland, OR - Inside Wireman | C11: =VLOOKUP(A11,'NECA Chapters(Debra)'!A:D,3,FALSE) -> Oregon-Columbia Chapter NECA | D11: =VLOOKUP(A11,'NECA Chapters(Debra)'!A:D,4,FALSE) -> Portland Division - 48 | E11: =VLOOKUP(A11,'NECA Chapters(Debra)'!A:D,2,FALSE) -> OR
A12: 57 L | B12: 57 L Interamountain Line Construction, UT - Lineman | C12: =VLOOKUP(A12,'NECA Chapters(Debra)'!A:D,3,FALSE) -> #N/A | D12: =VLOOKUP(A12,'NECA Chapters(Debra)'!A:D,4,FALSE) -> #N/A | E12: =VLOOKUP(A12,'NECA Chapters(Debra)'!A:D,2,FALSE) -> #N/A
A13: 60 | B13: 60 San Antonio, TX - Inside Wireman | C13: =VLOOKUP(A13,'NECA Chapters(Debra)'!A:D,3,FALSE) -> South Texas Chapter NECA | D13: =VLOOKUP(A13,'NECA Chapters(Debra)'!A:D,4,FALSE) -> San Antonio Division - 60 | E13: =VLOOKUP(A13,'NECA Chapters(Debra)'!A:D,2,FALSE) -> TX
A14: 66 L | B14: 66 L Pasadena, TX - Lineman | C14: =VLOOKUP(A14,'NECA Chapters(Debra)'!A:D,3,FALSE) -> #N/A | D14: =VLOOKUP(A14,'NECA Chapters(Debra)'!A:D,4,FALSE) -> #N/A | E14: =VLOOKUP(A14,'NECA Chapters(Debra)'!A:D,2,FALSE) -> #N/A
A15: 70 L | B15: 70 L - DC, KY, MD, VA, WV, DC - Lineman | C15: =VLOOKUP(A15,'NECA Chapters(Debra)'!A:D,3,FALSE) -> #N/A | D15: =VLOOKUP(A15,'NECA Chapters(Debra)'!A:D,4,FALSE) -> #N/A | E15: =VLOOKUP(A15,'NECA Chapters(Debra)'!A:D,2,FALSE) -> #N/A
A16: 72 | B16: 72 Waco, TX - Inside Wireman | C16: =VLOOKUP(A16,'NECA Chapters(Debra)'!A:D,3,FALSE) -> Central Texas Chapter NECA | D16: =VLOOKUP(A16,'NECA Chapters(Debra)'!A:D,4,FALSE) -> Waco Division - 72 | E16: =VLOOKUP(A16,'NECA Chapters(Debra)'!A:D,2,FALSE) -> TX
A17: 76 | B17: 76 Southwest WA - Inside Wireman | C17: =VLOOKUP(A17,'NECA Chapters(Debra)'!A:D,3,FALSE) -> Southwest Washington Chapter NECA | D17: =VLOOKUP(A17,'NECA Chapters(Debra)'!A:D,4,FALSE) -> Tacoma Division - 76 | E17: =VLOOKUP(A17,'NECA Chapters(Debra)'!A:D,2,FALSE) -> WA
A18: 80 | B18: 80 Chesapeake, VA - Inside Wireman | C18: =VLOOKUP(A18,'NECA Chapters(Debra)'!A:D,3,FALSE) -> Atlantic Coast Chapter NECA | D18: =VLOOKUP(A18,'NECA Chapters(Debra)'!A:D,4,FALSE) -> Tidewater Division - 80 | E18: =VLOOKUP(A18,'NECA Chapters(Debra)'!A:D,2,FALSE) -> VA
A19: 89 | B19: 89 San Diego, CA - Laborers | C19: =VLOOKUP(A19,'NECA Chapters(Debra)'!A:D,3,FALSE) -> Northwest Line Constructors Chapter NECA | D19: =VLOOKUP(A19,'NECA Chapters(Debra)'!A:D,4,FALSE) -> 0 | E19: =VLOOKUP(A19,'NECA Chapters(Debra)'!A:D,2,FALSE) -> WA
A20: 100 | B20: 100 Fresno, CA - Inside Wireman | C20: =VLOOKUP(A20,'NECA Chapters(Debra)'!A:D,3,FALSE) -> East Central California Chapter NECA | D20: =VLOOKUP(A20,'NECA Chapters(Debra)'!A:D,4,FALSE) -> Fresno Division - 100 | E20: =VLOOKUP(A20,'NECA Chapters(Debra)'!A:D,2,FALSE) -> CA
A21: 112 | B21: 112 Kennewick, WA - Inside Wireman | C21: =VLOOKUP(A21,'NECA Chapters(Debra)'!A:D,3,FALSE) -> Inland Empire Chapter NECA | D21: =VLOOKUP(A21,'NECA Chapters(Debra)'!A:D,4,FALSE) -> Western Division - 112 | E21: =VLOOKUP(A21,'NECA Chapters(Debra)'!A:D,2,FALSE) -> WA
A22: 143 | B22: 143 Harrisburg, PA - Inside Wireman | C22: =VLOOKUP(A22,'NECA Chapters(Debra)'!A:D,3,FALSE) -> Penn-Del-Jersey Chapter NECA | D22: =VLOOKUP(A22,'NECA Chapters(Debra)'!A:D,4,FALSE) -> Harrisburg Division - 143 | E22: =VLOOKUP(A22,'NECA Chapters(Debra)'!A:D,2,FALSE) -> PA
A23: 180 | B23: 180 Napa/Solano Counties, CA - Inside Wireman | C23: =VLOOKUP(A23,'NECA Chapters(Debra)'!A:D,3,FALSE) -> Northern California Chapter NECA | D23: =VLOOKUP(A23,'NECA Chapters(Debra)'!A:D,4,FALSE) -> Solano Napa Counties Div - 180 | E23: =VLOOKUP(A23,'NECA Chapters(Debra)'!A:D,2,FALSE) -> CA
A24: 191E | B24: 191E Everett, WA - Inside Wireman | C24: =VLOOKUP(A24,'NECA Chapters(Debra)'!A:D,3,FALSE) -> #N/A | D24: =VLOOKUP(A24,'NECA Chapters(Debra)'!A:D,4,FALSE) -> #N/A | E24: =VLOOKUP(A24,'NECA Chapters(Debra)'!A:D,2,FALSE) -> #N/A
A25: 196 L | B25: 196 L Huntley, IL - Lineman | C25: =VLOOKUP(A25,'NECA Chapters(Debra)'!A:D,3,FALSE) -> #N/A | D25: =VLOOKUP(A25,'NECA Chapters(Debra)'!A:D,4,FALSE) -> #N/A | E25: =VLOOKUP(A25,'NECA Chapters(Debra)'!A:D,2,FALSE) -> #N/A
A26: 209 | B26: Southern CA - Carpenters | C26: =VLOOKUP(A26,'NECA Chapters(Debra)'!A:D,3,FALSE) -> #N/A | D26: =VLOOKUP(A26,'NECA Chapters(Debra)'!A:D,4,FALSE) -> #N/A | E26: =VLOOKUP(A26,'NECA Chapters(Debra)'!A:D,2,FALSE) -> #N/A
A27: 220 L | B27: Southwestern, TX - Lineman | C27: =VLOOKUP(A27,'NECA Chapters(Debra)'!A:D,3,FALSE) -> #N/A | D27: =VLOOKUP(A27,'NECA Chapters(Debra)'!A:D,4,FALSE) -> #N/A | E27: =VLOOKUP(A27,'NECA Chapters(Debra)'!A:D,2,FALSE) -> #N/A
A28: 234 | B28: 234 Monterey/Santa Cruz , CA - Inside Wireman | C28: =VLOOKUP(A28,'NECA Chapters(Debra)'!A:D,3,FALSE) -> Monterey Bay California Chapter NECA | D28: =VLOOKUP(A28,'NECA Chapters(Debra)'!A:D,4,FALSE) -> Salinas Division - 234 | E28: =VLOOKUP(A28,'NECA Chapters(Debra)'!A:D,2,FALSE) -> CA
A29: 270 | B29: Northern CA - Laborers (Including locals 67, 73, 166, 185, 261, 294, 304, 324, 886, 1130) | C29: =VLOOKUP(A29,'NECA Chapters(Debra)'!A:D,3,FALSE) -> East Tennessee Chapter NECA | D29: =VLOOKUP(A29,'NECA Chapters(Debra)'!A:D,4,FALSE) -> Oak Ridge Division - 270 | E29: =VLOOKUP(A29,'NECA Chapters(Debra)'!A:D,2,FALSE) -> TN
A30: 280 | B30: 280 Springfield, OR - Inside Wireman | C30: =VLOOKUP(A30,'NECA Chapters(Debra)'!A:D,3,FALSE) -> Oregon-Pacific-Cascade Chapter NECA | D30: =VLOOKUP(A30,'NECA Chapters(Debra)'!A:D,4,FALSE) -> Cascade Div-Central Oregon-280 | E30: =VLOOKUP(A30,'NECA Chapters(Debra)'!A:D,2,FALSE) -> OR
A31: 291 | B31: 291 Boise, ID - Inside Wireman | C31: =VLOOKUP(A31,'NECA Chapters(Debra)'!A:D,3,FALSE) -> Idaho Chapter NECA | D31: =VLOOKUP(A31,'NECA Chapters(Debra)'!A:D,4,FALSE) -> Western Division - 291 | E31: =VLOOKUP(A31,'NECA Chapters(Debra)'!A:D,2,FALSE) -> ID
A32: 302 | B32: 302 Contra Costa County, CA - Inside Wireman | C32: =VLOOKUP(A32,'NECA Chapters(Debra)'!A:D,3,FALSE) -> Contra Costa Chapter NECA | D32: =VLOOKUP(A32,'NECA Chapters(Debra)'!A:D,4,FALSE) -> Martinez Division - 302 | E32: =VLOOKUP(A32,'NECA Chapters(Debra)'!A:D,2,FALSE) -> CA
A33: 332 | B33: 332 San Jose, CA - Inside Wireman | C33: =VLOOKUP(A33,'NECA Chapters(Debra)'!A:D,3,FALSE) -> Santa Clara Valley Chapter NECA | D33: =VLOOKUP(A33,'NECA Chapters(Debra)'!A:D,4,FALSE) -> San Jose Division - 332 | E33: =VLOOKUP(A33,'NECA Chapters(Debra)'!A:D,2,FALSE) -> CA
A34: 340 | B34: 340 Sacramento, CA - Inside Wireman | C34: =VLOOKUP(A34,'NECA Chapters(Debra)'!A:D,3,FALSE) -> Greater Sacramento Chapter NECA | D34: =VLOOKUP(A34,'NECA Chapters(Debra)'!A:D,4,FALSE) -> Sacramento Division - 340 | E34: =VLOOKUP(A34,'NECA Chapters(Debra)'!A:D,2,FALSE) -> CA
A35: 354 | B35: 354 Salt Lake, UT - Inside Wireman | C35: =VLOOKUP(A35,'NECA Chapters(Debra)'!A:D,3,FALSE) -> Intermountain Chapter NECA | D35: =VLOOKUP(A35,'NECA Chapters(Debra)'!A:D,4,FALSE) -> Utah Division - 354 | E35: =VLOOKUP(A35,'NECA Chapters(Debra)'!A:D,2,FALSE) -> UT
A36: 357 | B36: 357 Las Vegas, NV - Inside Wireman | C36: =VLOOKUP(A36,'NECA Chapters(Debra)'!A:D,3,FALSE) -> Southern Nevada Chapter NECA | D36: =VLOOKUP(A36,'NECA Chapters(Debra)'!A:D,4,FALSE) -> Las Vegas Division - 357 | E36: =VLOOKUP(A36,'NECA Chapters(Debra)'!A:D,2,FALSE) -> NV
A37: 379 | B37: 379 Charlotte, NC - Inside Wireman | C37: =VLOOKUP(A37,'NECA Chapters(Debra)'!A:D,3,FALSE) -> Atlantic Coast Chapter NECA | D37: =VLOOKUP(A37,'NECA Chapters(Debra)'!A:D,4,FALSE) -> Charlotte Division - 379 | E37: =VLOOKUP(A37,'NECA Chapters(Debra)'!A:D,2,FALSE) -> VA
A38: 401 | B38: 401 Reno, NV - Inside Wireman | C38: =VLOOKUP(A38,'NECA Chapters(Debra)'!A:D,3,FALSE) -> Greater Sacramento Chapter NECA | D38: =VLOOKUP(A38,'NECA Chapters(Debra)'!A:D,4,FALSE) -> Reno Division - 401 | E38: =VLOOKUP(A38,'NECA Chapters(Debra)'!A:D,2,FALSE) -> CA
A39: 405 | B39: Northern CA - Carpernters | C39: =VLOOKUP(A39,'NECA Chapters(Debra)'!A:D,3,FALSE) -> Iowa Chapter NECA | D39: =VLOOKUP(A39,'NECA Chapters(Debra)'!A:D,4,FALSE) -> Cedar Rapids Division - 405 | E39: =VLOOKUP(A39,'NECA Chapters(Debra)'!A:D,2,FALSE) -> IA
... A53: 583 | B53: 583 El Paso, TX - Inside Wireman | C53: =VLOOKUP(A53,'NECA Chapters(Debra)'!A:D,3,FALSE) -> El Paso Chapter NECA | D53: =VLOOKUP(A53,'NECA Chapters(Debra)'!A:D,4,FALSE) -> El Paso Division - 583 | E53: =VLOOKUP(A53,'NECA Chapters(Debra)'!A:D,2,FALSE) -> TX
...

Sheet NECA Chapters(Debra)
A1: IBEW LU | B1: Primary Affiliation: Mailing/Billing State/Province (text only) ↑ | C1: Primary Affiliation: Account Name ↑ | D1: Division Name ↑
A2: 1547 | B2: AK | C2: Alaska Chapter NECA | D2: Anchorage Division - 1547
A3: 136 | B3: AL | C3: Gulf Coast Chapter NECA | D3: Birmingham Division - 136
A4: 903 | B4: AL | C4: Gulf Coast Chapter NECA | D4: Gulfport Division - 903
A5: 505 | B5: AL | C5: Gulf Coast Chapter NECA | D5: Mobile Division - 505
A6: 558 | B6: AL | C6: Gulf Coast Chapter NECA | D6: Sheffield Division - 558
A7: 436 | B7: AR | C7: Arkansas Chapter NECA | D7: El Dorado Division - 436
A8: 700 | B8: AR | C8: Arkansas Chapter NECA | D8: Ft Smith Division - 700
A9: 1516 | B9: AR | C9: Arkansas Chapter NECA | D9: Jonesboro Division - 1516
A10: 295 | B10: AR | C10: Arkansas Chapter NECA | D10: Little Rock Division - 295
A11: 301 | B11: AR | C11: Arkansas Chapter NECA | D11: Texarkana Division - 301
A12: 640 | B12: AZ | C12: Arizona Chapter NECA | D12: Phoenix Division - 640
A13: 518 | B13: AZ | C13: Southern Arizona Chapter NECA | D13: Globe-Miami Division - 518
... A53: 508 | B53: GA | C53: Georgia Chapter NECA | D53: Eastern Division - 508
A54: 1316 | B54: GA | C54: Georgia Chapter NECA
A55: 1531 | B55: GA | C55: Georgia Chapter NECA | D55: Western Division-1531,1316
A56: 1186 | B56: HI | C56: Hawaii Chapter NECA | D56: Hawaii Division - 1186
A57: 405 | B57: IA | C57: Iowa Chapter NECA | D57: Cedar Rapids Division - 405
A58: 347 | B58: IA | C58: Iowa Chapter NECA | D58: Des Moines Division - 347
A59: 704 | B59: IA | C59: Iowa Chapter NECA | D59: Dubuque Division - 704
A60: 13 | B60: IA | C60: Iowa Chapter NECA | D60: Ottumwa Division - 13
A61: 231 | B61: IA | C61: Iowa Chapter NECA | D61: Sioux City Division - 231
A62: 288 | B62: IA | C62: Iowa Chapter NECA | D62: Waterloo Division - 288
A63: 145 | B63: IA | C63: Quad Cities Chapter NECA | D63: Quad Cities Division - 145
A64: 449 | B64: ID | C64: Idaho Chapter NECA | D64: Eastern Division - 449
A65: 291 | B65: ID | C65: Idaho Chapter NECA | D65: Western Division - 291
A66: 34 | B66: IL | C66: Central Illinois Chapter NECA | D66: Peoria Division - 34
... A105: 103 | B105: MA | C105: Boston Chapter NECA | D105: Boston Division - 103
A106: 1257 | B106: MA | C106: Boston Chapter NECA
A107: 567 | B107: MA | C107: Boston Chapter NECA | D107: Maine Division - 567, 1257
A108: 490 | B108: MA | C108: Boston Chapter NECA | D108: New Hampshire Division - 490
A109: 96 | B109: MA | C109: Central Massachusetts Chapter NECA | D109: Worcester Division - 96
A110: 7 | B110: MA | C110: Western Massachusetts Chapter NECA | D110: Springfield Division - 7
A111: 24 | B111: MD | C111: Maryland Chapter NECA | D111: Baltimore Division - 24
A112: 307 | B112: MD | C112: Maryland Chapter NECA | D112: Western Maryland Division - 307
A113: 445 | B113: MI | C113: Michigan Chapter NECA | D113: Battle Creek Division -445
A114: 692 | B114: MI | C114: Michigan Chapter NECA | D114: Bay City Division - 692
A115: 948 | B115: MI | C115: Michigan Chapter NECA | D115: Flint Division - 948
A116: 131 | B116: MI | C116: Michigan Chapter NECA | D116: Kalamazoo Division - 131
A117: 665 | B117: MI | C117: Michigan Chapter NECA | D117: Lansing Division - 665
...

Sheet NECA Committees REI reps
A1: 2026 NECA National Committees & Task Forces
A2: Ron Clarkson | B2: District 9 | C2: Rosendin Electric | D2: Technology Systems Integration Task Force
A3: Andrew Harrington | B3: District 5 | C3: Rosendin Electric | D3: Codes and Standards Committee
A4: Steven Emert | B4: District 9 | C4: Rosendin Electric | D4: Codes and Standards Committee
A5: Clint Summers | B5: District 9 | C5: Rosendin Electric | D5: Codes and Standards Committee
A6: Summer Reese | B6: District 9 | C6: Rosendin Electric | D6: Women in NECA
A7: Brice Merritt | B7: District 9 | C7: Rosendin Electric | D7: Future Leaders Task Force
A8: Summer Reese | B8: District 9 | C8: Rosendin Electric | D8: Future Leaders Task Force
A9: Noelle Sebastian | B9: District 9 | C9: Rosendin Electric | D9: Future Leaders Task Force,Women in NECA

Sheet NECA REI Contact List
A1: Chapter | B1: IBEW Local | C1: Representative | D1: Phone | E1: E-mail
A2: Arizona | B2: 640 | C2: Jason Karseboom | D2: (480) 581-4100 | E2: jkarseboom@rosendin.com
A3: Oregon-Columbia | B3: 48 | C3: Robert John | D3: (503) 615-8189 | E3: rjohn@rosendin.com
A4: Southern Nevada | B4: 357 | C4: Chris Meiers | D4: (702) 258-1400 | E4: cmeiers@rosendin.com
A5: Inland Empire | B5: 112 | C5: Tom Sorley | D5: (503) 615-8189 | E5: tsorley@rosendin.com
A6: Greater Sacramento | B6: 340 | C6: Tamara Rapozo | D6: (916) 285-0421 | E6: trapozo@rosendin.com
A7: Oregon-Pacific-Cascade | B7: 280 | C7: Timothy Schierling | D7: (503) 615-8189 | E7: tschierling@rosendin.com
A8: Washington DC | B8: 26 | C8: Keith Douglas | D8: (703) 707-8200 | E8: kdouglas@rosendin.com
A9: South Texas | B9: 60 | C9: Justin Prince | D9: (512) 272-8841 | E9: jprince@rosendin.com
A10: Southeast Texas | B10: 716 | C10: Shaun Mahan | D10: (512) 272-8841 | E10: smahan@rosendin.com
A11: Southeast Texas | B11: 278 | C11: Shaun Mahan | D11: (512) 272-8841 | E11: smahan@rosendin.com
A12: Maryland | B12: 24 | C12: Jeff Marshal | D12: (410) 787-8374 | E12: jmarshall@rosendin.com
A13: San Diego | B13: 569 | C13: Jerry Jordan | D13: (714) 521-8113 | E13: jjordan@rosendin.com
... A17: Central Texas | B17: 520 | C17: Shaun Mahan | D17: (512) 272-8841 | E17: smahan@rosendin.com
A18: Northern California | B18: 595 | C18: Aaron W Olson | D18: (408) 286-2800 | E18: aolson@rosendin.com
A19: Hawaii | B19: 1186 | C19: Ryan Chun | D19: (808) 200-5967 | E19: rchun@rosendin.com
A20: Southeast Texas | B20: 1015 | C20: Shaun Mahan | D20: (512) 272-8841 | E20: smahan@rosendin.com
A21: Northwest Line Constructors | B21: Multiple | C21: Robert John | D21: (503) 615-8189 | E21: rjohn@rosendin.com
A22: Tennessee | B22: 429 | C22: Tullie Louder | D22: (615) 461-2300 | E22: tlouder@rosendin.com
A23: Santa Clara | B23: 332 | C23: Jim Millett | D23: (408) 286-2800 | E23: jmillett@rosendin.com
A24: Los Angeles | B24: 11 | C24: Dan Domenici | D24: (657) 276-0600 | E24: ddomenici@rosendin.com
A25: San Francisco | B25: 6 | C25: Tom McIntosh | D25: (415) 495-9300 | E25: tmcintosh@rosendin.com
A26: Idaho | B26: 291 | C26: Robert John | D26: (541) 233-7769 | E26: rjohn@rosendin.com
A27: Greater Sacramento | B27: 401 | C27: Ryan Gill | D27: (775) 332-5800 | E27: rgill@rosendin.com
